<?xml version="1.0" ?>
<!-- =================================================================================== -->
<!-- |    This document was autogenerated by xacro from phoenixbot.urdf.xacro          | -->
<!-- |    EDITING THIS FILE BY HAND IS NOT RECOMMENDED                                 | -->
<!-- =================================================================================== -->
<robot name="phoenixbot" xmlns:xacro="http://www.ros.org/wiki/xacro">
  <gazebo>
    <plugin filename="libgazebo_ros_control.so" name="gazebo_ros_control">
      <robotSimType>gazebo_ros_control/DefaultRobotHWSim</robotSimType>
    </plugin>
  </gazebo>
  <gazebo>
    <plugin filename="libgazebo_ros_imu.so" name="imu_plugin">
      <alwaysOn>true</alwaysOn>
      <bodyName>base_link</bodyName>
      <topicName>imu_data</topicName>
      <serviceName>imu_service</serviceName>
      <gaussianNoise>0.0</gaussianNoise>
      <updateRate>20.0</updateRate>
    </plugin>
  </gazebo>
  <gazebo reference="laser_link">
    <sensor name="laser" type="ray">
      <pose>0 0 0 0 0 0</pose>
      <visualize>true</visualize>
      <update_rate>40</update_rate>
      <ray>
        <scan>
          <horizontal>
            <samples>720</samples>
            <resolution>1</resolution>
            <min_angle>-1.570796</min_angle>
            <max_angle>1.570796</max_angle>
          </horizontal>
        </scan>
        <range>
          <min>0.5</min>
          <max>30.0</max>
          <resolution>0.01</resolution>
        </range>
        <noise>
          <type>gaussian</type>
          <mean>0.0</mean>
          <stddev>0.01</stddev>
        </noise>
      </ray>
      <plugin filename="libgazebo_ros_laser.so" name="gazebo_ros_laser_controller">
        <topicName>/scan</topicName>
        <frameName>laser_link</frameName>
      </plugin>
    </sensor>
  </gazebo>
  <gazebo reference="camera">
    <sensor name="camera" type="camera">
      <update_rate>30.0</update_rate>
      <camera name="camera">
        <horizontal_fov>1.3962634</horizontal_fov>
        <image>
          <width>800</width>
          <height>600</height>
          <format>R8G8B8</format>
        </image>
        <clip>
          <near>0.02</near>
          <far>300</far>
        </clip>
        <noise>
          <type>gaussian</type>
          <mean>0.0</mean>
          <stddev>0.007</stddev>
        </noise>
      </camera>
      <plugin filename="libgazebo_ros_camera.so" name="camera_controller">
        <alwaysOn>true</alwaysOn>
        <updateRate>0.0</updateRate>
        <cameraName>phoenixbot/front_camera</cameraName>
        <imageTopicName>image_raw</imageTopicName>
        <cameraInfoTopicName>camera_info</cameraInfoTopicName>
        <frameName>camera</frameName>
        <hackBaseline>0.07</hackBaseline>
        <distortionK1>0.0</distortionK1>
        <distortionK2>0.0</distortionK2>
        <distortionK3>0.0</distortionK3>
        <distortionT1>0.0</distortionT1>
        <distortionT2>0.0</distortionT2>
      </plugin>
    </sensor>
  </gazebo>
  <link name="base_link"/>
  <link name="base_footprint"/>
  <joint name="base_link_joint" type="fixed">
    <parent link="base_link"/>
    <child link="chassis"/>
    <origin xyz="0 0 0.0254"/>
  </joint>
  <joint name="base_footprint_joint" type="fixed">
    <parent link="base_link"/>
    <child link="base_footprint"/>
    <origin xyz="0 0 0"/>
  </joint>
  <link name="chassis">
    <visual>
      <origin rpy="1.57079632679 0 1.57079632679"/>
      <geometry>
        <mesh filename="package://phoenixbot_description/meshes/phoenixbotbody.stl" scale="0.01 0.01 0.01"/>
        <!--<box size="${28.31 * IN} ${27.50 * IN} ${3.33 * IN}"/>-->
      </geometry>
    </visual>
    <collision>
      <geometry>
        <box size="0.719074 0.6985 0.084582"/>
      </geometry>
    </collision>
    <inertial>
      pi
            
      <mass value="6.80388"/>
      <inertia ixx="0.297228366542" ixy="0" ixz="0" iyy="0.569807751762" iyz="0" izz="0.280692008235"/>
    </inertial>
  </link>
  <link name="left_wheel">
    <visual>
      <origin rpy="0 0 1.57079632679"/>
      <geometry>
        <mesh filename="package://phoenixbot_description/meshes/middle2.stl" scale="0.01 0.01 0.01"/>
        <!--<cylinder length="${1 * IN}" radius="${2 * IN}"/>-->
      </geometry>
    </visual>
    <collision>
      <origin rpy="1.57079632679 0 0"/>
      <geometry>
        <cylinder length="0.0254" radius="0.0508"/>
      </geometry>
    </collision>
    <inertial>
      <mass value="0.14061352"/>
      <inertia ixx="9.82780701101e-05" ixy="0" ixz="0" iyy="9.82780701101e-05" iyz="0" izz="9.82780701101e-05"/>
    </inertial>
  </link>
  <link name="left_fwheel">
    <visual>
      <origin rpy="0 0 1.57079632679"/>
      <geometry>
        <mesh filename="package://phoenixbot_description/meshes/top2.stl" scale="0.01 0.01 0.01"/>
        <!--<cylinder length="${1 * IN}" radius="${2 * IN}"/>-->
      </geometry>
    </visual>
    <collision>
      <origin rpy="1.57079632679 0 0"/>
      <geometry>
        <cylinder length="0.0254" radius="0.0508"/>
      </geometry>
    </collision>
    <inertial>
      <mass value="0.14061352"/>
      <inertia ixx="9.82780701101e-05" ixy="0" ixz="0" iyy="9.82780701101e-05" iyz="0" izz="9.82780701101e-05"/>
    </inertial>
  </link>
  <link name="left_rwheel">
    <visual>
      <origin rpy="0 0 1.57079632679"/>
      <geometry>
        <mesh filename="package://phoenixbot_description/meshes/bottom2.stl" scale="0.01 0.01 0.01"/>
        <!--<cylinder length="${1 * IN}" radius="${2 * IN}"/>-->
      </geometry>
    </visual>
    <collision>
      <origin rpy="1.57079632679 0 0"/>
      <geometry>
        <cylinder length="0.0254" radius="0.0508"/>
      </geometry>
    </collision>
    <inertial>
      <mass value="0.14061352"/>
      <inertia ixx="9.82780701101e-05" ixy="0" ixz="0" iyy="9.82780701101e-05" iyz="0" izz="9.82780701101e-05"/>
    </inertial>
  </link>
  <joint name="left_wheel_joint" type="continuous">
    <axis xyz="0 1 0"/>
    <origin xyz="0 0.325628 0"/>
    <parent link="base_link"/>
    <child link="left_wheel"/>
  </joint>
  <joint name="left_fwheel_joint" type="continuous">
    <axis xyz="0 1 0"/>
    <origin xyz="0.272542 0.325628 0.00635"/>
    <parent link="base_link"/>
    <child link="left_fwheel"/>
    <mimic joint="left_wheel_joint"/>
  </joint>
  <joint name="left_rwheel_joint" type="continuous">
    <axis xyz="0 1 0"/>
    <origin xyz="-0.272542 0.325628 0.00635"/>
    <parent link="base_link"/>
    <child link="left_rwheel"/>
    <mimic joint="left_wheel_joint"/>
  </joint>
  <transmission name="left_wheel_transmission">
    <type>transmission_interface/SimpleTransmission</type>
    <joint name="left_wheel_joint">
      <hardwareInterface>hardware_interface/VelocityJointInterface</hardwareInterface>
    </joint>
    <actuator name="left_motor">
      <hardwareInterface>hardware_interface/VelocityJointInterface</hardwareInterface>
      <mechanicalReduction>1</mechanicalReduction>
    </actuator>
  </transmission>
  <link name="right_wheel">
    <visual>
      <origin rpy="0 0 1.57079632679"/>
      <geometry>
        <mesh filename="package://phoenixbot_description/meshes/middle1.stl" scale="0.01 0.01 0.01"/>
        <!--<cylinder length="${1 * IN}" radius="${2 * IN}"/>-->
      </geometry>
    </visual>
    <collision>
      <origin rpy="1.57079632679 0 0"/>
      <geometry>
        <cylinder length="0.0254" radius="0.0508"/>
      </geometry>
    </collision>
    <inertial>
      <mass value="0.14061352"/>
      <inertia ixx="9.82780701101e-05" ixy="0" ixz="0" iyy="9.82780701101e-05" iyz="0" izz="9.82780701101e-05"/>
    </inertial>
  </link>
  <link name="right_fwheel">
    <visual>
      <origin rpy="0 0 1.57079632679"/>
      <geometry>
        <mesh filename="package://phoenixbot_description/meshes/top1.stl" scale="0.01 0.01 0.01"/>
        <!--<cylinder length="${1 * IN}" radius="${2 * IN}"/>-->
      </geometry>
    </visual>
    <collision>
      <origin rpy="1.57079632679 0 0"/>
      <geometry>
        <cylinder length="0.0254" radius="0.0508"/>
      </geometry>
    </collision>
    <inertial>
      <mass value="0.14061352"/>
      <inertia ixx="9.82780701101e-05" ixy="0" ixz="0" iyy="9.82780701101e-05" iyz="0" izz="9.82780701101e-05"/>
    </inertial>
  </link>
  <link name="right_rwheel">
    <visual>
      <origin rpy="0 0 1.57079632679"/>
      <geometry>
        <mesh filename="package://phoenixbot_description/meshes/bottom1.stl" scale="0.01 0.01 0.01"/>
        <!--<cylinder length="${1 * IN}" radius="${2 * IN}"/>-->
      </geometry>
    </visual>
    <collision>
      <origin rpy="1.57079632679 0 0"/>
      <geometry>
        <cylinder length="0.0254" radius="0.0508"/>
      </geometry>
    </collision>
    <inertial>
      <mass value="0.14061352"/>
      <inertia ixx="9.82780701101e-05" ixy="0" ixz="0" iyy="9.82780701101e-05" iyz="0" izz="9.82780701101e-05"/>
    </inertial>
  </link>
  <joint name="right_wheel_joint" type="continuous">
    <axis xyz="0 1 0"/>
    <origin xyz="0 -0.325628 0"/>
    <parent link="base_link"/>
    <child link="right_wheel"/>
  </joint>
  <joint name="right_fwheel_joint" type="continuous">
    <axis xyz="0 1 0"/>
    <origin xyz="0.272542 -0.325628 0.00635"/>
    <parent link="base_link"/>
    <child link="right_fwheel"/>
    <mimic joint="right_wheel_joint"/>
  </joint>
  <joint name="right_rwheel_joint" type="continuous">
    <axis xyz="0 1 0"/>
    <origin xyz="-0.272542 -0.325628 0.00635"/>
    <parent link="base_link"/>
    <child link="right_rwheel"/>
    <mimic joint="right_wheel_joint"/>
  </joint>
  <transmission name="right_wheel_transmission">
    <type>transmission_interface/SimpleTransmission</type>
    <joint name="right_wheel_joint">
      <hardwareInterface>hardware_interface/VelocityJointInterface</hardwareInterface>
    </joint>
    <actuator name="right_motor">
      <hardwareInterface>hardware_interface/VelocityJointInterface</hardwareInterface>
      <mechanicalReduction>1</mechanicalReduction>
    </actuator>
  </transmission>
  <link name="simon_arm">
    <visual>
      <origin rpy="0 0 0"/>
      <geometry>
        <mesh filename="package://phoenixbot_description/meshes/simonArm.stl"/>
      </geometry>
    </visual>
    <collision>
      <origin xyz="-0.3556 0 0"/>
      <geometry>
        <box size="0.7493 0.6096 0.0762"/>
      </geometry>
    </collision>
    <inertial>
      <mass value="1.814368"/>
      <inertia ixx="0.297228366542" ixy="0" ixz="0" iyy="0.569807751762" iyz="0" izz="0.280692008235"/>
    </inertial>
  </link>
  <link name="solenoid1"/>
  <link name="solenoid2"/>
  <link name="solenoid3"/>
  <link name="solenoid4"/>
  <joint name="solenoid1_joint" type="fixed">
    <parent link="simon_arm"/>
    <child link="solenoid1"/>
    <origin xyz="-0.7112 -0.127 0"/>
  </joint>
  <joint name="solenoid2_joint" type="fixed">
    <parent link="simon_arm"/>
    <child link="solenoid2"/>
    <origin xyz="-0.7112 0.127 0"/>
  </joint>
  <joint name="solenoid3_joint" type="fixed">
    <parent link="simon_arm"/>
    <child link="solenoid3"/>
    <origin xyz="-0.4572 0.127 0"/>
  </joint>
  <joint name="solenoid4_joint" type="fixed">
    <parent link="simon_arm"/>
    <child link="solenoid4"/>
    <origin xyz="-0.4572 -0.127 0"/>
  </joint>
  <joint name="simon_arm_joint" type="revolute">
    <axis xyz="0 1 0"/>
    <origin rpy="0 1.57079632679 0" xyz="-0.272542 0 0.0762"/>
    <parent link="chassis"/>
    <child link="simon_arm"/>
    <limit effort="20.0" lower="0" upper="1.57" velocity="1.6"/>
  </joint>
  <transmission name="simon_arm_transmission">
    <type>transmission_interface/SimpleTransmission</type>
    <joint name="simon_arm_joint">
      <hardwareInterface>hardware_interface/VelocityJointInterface</hardwareInterface>
    </joint>
    <actuator name="simon_motor">
      <hardwareInterface>hardware_interface/VelocityJointInterface</hardwareInterface>
      <mechanicalReduction>1</mechanicalReduction>
    </actuator>
  </transmission>
  <joint name="pulley_joint" type="fixed">
    <parent link="chassis"/>
    <child link="pulley_center"/>
    <origin xyz="0.4318 0 0.1778"/>
  </joint>
  <link name="pulley_center">
    <visual>
      <origin xyz="-0.0508 0 -0.0508"/>
      <geometry>
        <box size="0.1016 0.1016 0.1778"/>
      </geometry>
    </visual>
    <collision>
      <origin xyz="-0.0508 0 -0.0508"/>
      <geometry>
        <box size="0.1016 0.1016 0.1778"/>
      </geometry>
    </collision>
    <inertial>
      <mass value="0.14061352"/>
      <inertia ixx="3.02394061877e-05" ixy="0" ixz="0" iyy="3.02394061877e-05" iyz="0" izz="3.02394061877e-05"/>
    </inertial>
  </link>
  <link name="left_rope_wheel">
    <visual>
      <origin rpy="1.57079632679 0 1.57079632679" xyz="0.0127 0 0"/>
      <geometry>
        <cylinder length="0.0254" radius="0.0254"/>
      </geometry>
    </visual>
    <collision>
      <origin rpy="1.57079632679 0 1.57079632679" xyz="0.0127 0 0"/>
      <geometry>
        <cylinder length="0.0254" radius="0.0254"/>
      </geometry>
    </collision>
    <inertial>
      <mass value="0.14061352"/>
      <inertia ixx="3.02394061877e-05" ixy="0" ixz="0" iyy="3.02394061877e-05" iyz="0" izz="3.02394061877e-05"/>
    </inertial>
  </link>
  <link name="right_rope_wheel">
    <visual>
      <origin rpy="1.57079632679 0 1.57079632679" xyz="0.0127 0 0"/>
      <geometry>
        <cylinder length="0.0254" radius="0.0254"/>
      </geometry>
    </visual>
    <collision>
      <origin rpy="1.57079632679 0 1.57079632679" xyz="0.0127 0 0"/>
      <geometry>
        <cylinder length="0.0254" radius="0.0254"/>
      </geometry>
    </collision>
    <inertial>
      <mass value="0.14061352"/>
      <inertia ixx="3.02394061877e-05" ixy="0" ixz="0" iyy="3.02394061877e-05" iyz="0" izz="3.02394061877e-05"/>
    </inertial>
  </link>
  <joint name="rope_joint" type="continuous">
    <axis xyz="1 0 0"/>
    <origin xyz="0 0.03175 0"/>
    <parent link="pulley_center"/>
    <child link="left_rope_wheel"/>
  </joint>
  <joint name="rope_joint_slave" type="continuous">
    <axis xyz="1 0 0"/>
    <origin xyz="0 -0.03175 0"/>
    <parent link="pulley_center"/>
    <child link="right_rope_wheel"/>
    <mimic joint="rope_joint" multiplier="-1"/>
  </joint>
  <transmission name="rope_transmission">
    <type>transmission_interface/SimpleTransmission</type>
    <joint name="rope_joint">
      <hardwareInterface>hardware_interface/VelocityJointInterface</hardwareInterface>
    </joint>
    <actuator name="rope_motor">
      <hardwareInterface>hardware_interface/VelocityJointInterface</hardwareInterface>
      <mechanicalReduction>1</mechanicalReduction>
    </actuator>
  </transmission>
  <link name="camera"/>
  <joint name="camera_joint" type="fixed">
    <parent link="base_link"/>
    <child link="camera"/>
    <origin rpy="0 -0.1 0" xyz="0.123825 -0.365125 0.358775"/>
  </joint>
  <link name="imu_base_link"/>
  <joint name="imu_joint" type="fixed">
    <parent link="base_link"/>
    <child link="imu_base_link"/>
    <origin xyz="0 0.0254 0"/>
  </joint>
  <link name="laser_link"/>
  <joint name="laser_joint" type="fixed">
    <parent link="base_link"/>
    <child link="laser_link"/>
    <origin xyz="0.272542 0 0.0762"/>
  </joint>
</robot>

